INFO:werkzeug: * Running on http://127.0.0.1:5000/ (Press CTRL+C to quit)
INFO:werkzeug:127.0.0.1 - - [03/Dec/2018 15:53:47] "GET / HTTP/1.1" 200 -
ERROR:flask.app:Exception on /new_patient [POST]
Traceback (most recent call last):
  File "/Library/Frameworks/Python.framework/Versions/3.7/lib/python3.7/site-packages/pymodm/connection.py", line 75, in _get_connection
    return _CONNECTIONS[alias]
KeyError: 'default'

During handling of the above exception, another exception occurred:

Traceback (most recent call last):
  File "/Library/Frameworks/Python.framework/Versions/3.7/lib/python3.7/site-packages/flask/app.py", line 2292, in wsgi_app
    response = self.full_dispatch_request()
  File "/Library/Frameworks/Python.framework/Versions/3.7/lib/python3.7/site-packages/flask/app.py", line 1815, in full_dispatch_request
    rv = self.handle_user_exception(e)
  File "/Library/Frameworks/Python.framework/Versions/3.7/lib/python3.7/site-packages/flask/app.py", line 1718, in handle_user_exception
    reraise(exc_type, exc_value, tb)
  File "/Library/Frameworks/Python.framework/Versions/3.7/lib/python3.7/site-packages/flask/_compat.py", line 35, in reraise
    raise value
  File "/Library/Frameworks/Python.framework/Versions/3.7/lib/python3.7/site-packages/flask/app.py", line 1813, in full_dispatch_request
    rv = self.dispatch_request()
  File "/Library/Frameworks/Python.framework/Versions/3.7/lib/python3.7/site-packages/flask/app.py", line 1799, in dispatch_request
    return self.view_functions[rule.endpoint](**req.view_args)
  File "/Users/deepthinacharaju/Documents/Duke/Class/Fall 2018/BME590/bme590final/server.py", line 45, in add_new_patient
    patient.save()
  File "/Library/Frameworks/Python.framework/Versions/3.7/lib/python3.7/site-packages/pymodm/base/models.py", line 474, in save
    result = self._mongometa.collection.replace_one(
  File "/Library/Frameworks/Python.framework/Versions/3.7/lib/python3.7/site-packages/pymodm/base/options.py", line 60, in collection
    coll = _get_db(self.connection_alias).get_collection(
  File "/Library/Frameworks/Python.framework/Versions/3.7/lib/python3.7/site-packages/pymodm/connection.py", line 85, in _get_db
    return _get_connection(alias).database
  File "/Library/Frameworks/Python.framework/Versions/3.7/lib/python3.7/site-packages/pymodm/connection.py", line 80, in _get_connection
    tb)
  File "/Library/Frameworks/Python.framework/Versions/3.7/lib/python3.7/site-packages/pymodm/compat.py", line 35, in reraise
    raise exctype(str(value)).with_traceback(trace)
  File "/Library/Frameworks/Python.framework/Versions/3.7/lib/python3.7/site-packages/pymodm/connection.py", line 75, in _get_connection
    return _CONNECTIONS[alias]
ValueError: No such alias 'default'. Did you forget to call connect()?
INFO:werkzeug:127.0.0.1 - - [03/Dec/2018 15:53:47] "POST /new_patient HTTP/1.1" 500 -
